<?xml version="1.0" encoding="UTF-8"?>
<!-- Generated by org.testng.reporters.JUnitXMLReporter -->
<testsuite hostname="admin-PC" ignored="0" name="login" tests="4" failures="2" timestamp="15 六月 2018 07:29:57 GMT" time="0.037" errors="0">
  <testcase name="test2" time="0.01" classname="com.tester.extend.demo.TestMethodsDemo"/>
  <testcase name="test1" time="0.01" classname="com.tester.extend.demo.TestMethodsDemo">
    <failure type="java.lang.AssertionError" message="expected [2] but found [1]">
      <![CDATA[java.lang.AssertionError: expected [2] but found [1]
at com.tester.extend.demo.TestMethodsDemo.test1(TestMethodsDemo.java:10)
at java.util.concurrent.ThreadPoolExecutor.runWorker(ThreadPoolExecutor.java:1149)
at java.util.concurrent.ThreadPoolExecutor$Worker.run(ThreadPoolExecutor.java:624)
at java.lang.Thread.run(Thread.java:748)
... Removed 16 stack frames]]>
    </failure>
  </testcase> <!-- test1 -->
  <testcase name="test3" time="0.0" classname="com.tester.extend.demo.TestMethodsDemo"/>
  <testcase name="test4" time="0.001" classname="com.tester.extend.demo.TestMethodsDemo">
    <failure type="java.lang.RuntimeException" message="这是自己抛出的异常测试">
      <![CDATA[java.lang.RuntimeException: 这是自己抛出的异常测试
at com.tester.extend.demo.TestMethodsDemo.test4(TestMethodsDemo.java:23)
at java.util.concurrent.ThreadPoolExecutor.runWorker(ThreadPoolExecutor.java:1149)
at java.util.concurrent.ThreadPoolExecutor$Worker.run(ThreadPoolExecutor.java:624)
at java.lang.Thread.run(Thread.java:748)
... Removed 10 stack frames]]>
    </failure>
  </testcase> <!-- test4 -->
</testsuite> <!-- login -->
