<?xml version="1.0" encoding="UTF-8"?>
<testng-results skipped="0" failed="2" ignored="0" total="4" passed="2">
  <reporter-output>
    <line>
      <![CDATA[这是自己写的测试报告]]>
    </line>
  </reporter-output>
  <suite name="Suite" duration-ms="37" started-at="2018-06-15T07:29:57Z" finished-at="2018-06-15T07:29:57Z">
    <groups>
    </groups>
    <test name="login" duration-ms="37" started-at="2018-06-15T07:29:57Z" finished-at="2018-06-15T07:29:57Z">
      <class name="com.tester.extend.demo.TestMethodsDemo">
        <test-method status="PASS" signature="test2()[pri:0, instance:com.tester.extend.demo.TestMethodsDemo@475530b9]" name="test2" duration-ms="10" started-at="2018-06-15T07:29:57Z" finished-at="2018-06-15T07:29:57Z">
          <reporter-output>
          </reporter-output>
        </test-method> <!-- test2 -->
        <test-method status="FAIL" signature="test1()[pri:0, instance:com.tester.extend.demo.TestMethodsDemo@475530b9]" name="test1" duration-ms="10" started-at="2018-06-15T07:29:57Z" finished-at="2018-06-15T07:29:57Z">
          <exception class="java.lang.AssertionError">
            <message>
              <![CDATA[expected [2] but found [1]]]>
            </message>
            <full-stacktrace>
              <![CDATA[java.lang.AssertionError: expected [2] but found [1]
at org.testng.Assert.fail(Assert.java:96)
at org.testng.Assert.failNotEquals(Assert.java:776)
at org.testng.Assert.assertEqualsImpl(Assert.java:137)
at org.testng.Assert.assertEquals(Assert.java:118)
at org.testng.Assert.assertEquals(Assert.java:652)
at org.testng.Assert.assertEquals(Assert.java:662)
at com.tester.extend.demo.TestMethodsDemo.test1(TestMethodsDemo.java:10)
at sun.reflect.NativeMethodAccessorImpl.invoke0(Native Method)
at sun.reflect.NativeMethodAccessorImpl.invoke(NativeMethodAccessorImpl.java:62)
at sun.reflect.DelegatingMethodAccessorImpl.invoke(DelegatingMethodAccessorImpl.java:43)
at java.lang.reflect.Method.invoke(Method.java:498)
at org.testng.internal.MethodInvocationHelper.invokeMethod(MethodInvocationHelper.java:124)
at org.testng.internal.Invoker.invokeMethod(Invoker.java:580)
at org.testng.internal.Invoker.invokeTestMethod(Invoker.java:716)
at org.testng.internal.Invoker.invokeTestMethods(Invoker.java:988)
at org.testng.internal.TestMethodWorker.invokeTestMethods(TestMethodWorker.java:125)
at org.testng.internal.TestMethodWorker.run(TestMethodWorker.java:109)
at java.util.concurrent.ThreadPoolExecutor.runWorker(ThreadPoolExecutor.java:1149)
at java.util.concurrent.ThreadPoolExecutor$Worker.run(ThreadPoolExecutor.java:624)
at java.lang.Thread.run(Thread.java:748)
]]>
            </full-stacktrace>
          </exception> <!-- java.lang.AssertionError -->
          <reporter-output>
          </reporter-output>
        </test-method> <!-- test1 -->
        <test-method status="PASS" signature="test3()[pri:0, instance:com.tester.extend.demo.TestMethodsDemo@475530b9]" name="test3" duration-ms="0" started-at="2018-06-15T07:29:57Z" finished-at="2018-06-15T07:29:57Z">
          <reporter-output>
          </reporter-output>
        </test-method> <!-- test3 -->
        <test-method status="FAIL" signature="test4()[pri:0, instance:com.tester.extend.demo.TestMethodsDemo@475530b9]" name="test4" duration-ms="1" started-at="2018-06-15T07:29:57Z" finished-at="2018-06-15T07:29:57Z">
          <exception class="java.lang.RuntimeException">
            <message>
              <![CDATA[这是自己抛出的异常测试]]>
            </message>
            <full-stacktrace>
              <![CDATA[java.lang.RuntimeException: 这是自己抛出的异常测试
at com.tester.extend.demo.TestMethodsDemo.test4(TestMethodsDemo.java:23)
at sun.reflect.NativeMethodAccessorImpl.invoke0(Native Method)
at sun.reflect.NativeMethodAccessorImpl.invoke(NativeMethodAccessorImpl.java:62)
at sun.reflect.DelegatingMethodAccessorImpl.invoke(DelegatingMethodAccessorImpl.java:43)
at java.lang.reflect.Method.invoke(Method.java:498)
at org.testng.internal.MethodInvocationHelper.invokeMethod(MethodInvocationHelper.java:124)
at org.testng.internal.Invoker.invokeMethod(Invoker.java:580)
at org.testng.internal.Invoker.invokeTestMethod(Invoker.java:716)
at org.testng.internal.Invoker.invokeTestMethods(Invoker.java:988)
at org.testng.internal.TestMethodWorker.invokeTestMethods(TestMethodWorker.java:125)
at org.testng.internal.TestMethodWorker.run(TestMethodWorker.java:109)
at java.util.concurrent.ThreadPoolExecutor.runWorker(ThreadPoolExecutor.java:1149)
at java.util.concurrent.ThreadPoolExecutor$Worker.run(ThreadPoolExecutor.java:624)
at java.lang.Thread.run(Thread.java:748)
]]>
            </full-stacktrace>
          </exception> <!-- java.lang.RuntimeException -->
          <reporter-output>
            <line>
              <![CDATA[这是自己写的测试报告]]>
            </line>
          </reporter-output>
        </test-method> <!-- test4 -->
      </class> <!-- com.tester.extend.demo.TestMethodsDemo -->
    </test> <!-- login -->
  </suite> <!-- Suite -->
</testng-results>
